20.42 Downloading torch-2.0.1-cp311-cp311-manylinux1_x86_64.whl (619.9 MB)
46.73    ━━━━━━━━━━━━━━━━━━━━━━━━                 372.0/619.9 MB 33.1 MB/s eta 0:00:08
46.73 ERROR: Exception:
46.73 Traceback (most recent call last):
46.73   File "/usr/local/lib/python3.11/site-packages/pip/_vendor/urllib3/response.py", line 438, in _error_catcher
46.73     yield
46.73   File "/usr/local/lib/python3.11/site-packages/pip/_vendor/urllib3/response.py", line 561, in read
46.73     data = self._fp_read(amt) if not fp_closed else b""
46.73            ^^^^^^^^^^^^^^^^^^
46.73   File "/usr/local/lib/python3.11/site-packages/pip/_vendor/urllib3/response.py", line 527, in _fp_read
46.73     return self._fp.read(amt) if amt is not None else self._fp.read()
46.73            ^^^^^^^^^^^^^^^^^^
46.73   File "/usr/local/lib/python3.11/site-packages/pip/_vendor/cachecontrol/filewrapper.py", line 90, in read
46.73     data = self.__fp.read(amt)
46.73            ^^^^^^^^^^^^^^^^^^^
46.73   File "/usr/local/lib/python3.11/http/client.py", line 473, in read
46.73     s = self.fp.read(amt)
46.73         ^^^^^^^^^^^^^^^^^
46.73   File "/usr/local/lib/python3.11/socket.py", line 706, in readinto
46.73     return self._sock.recv_into(b)
46.73            ^^^^^^^^^^^^^^^^^^^^^^^
46.73   File "/usr/local/lib/python3.11/ssl.py", line 1315, in recv_into
46.73     return self.read(nbytes, buffer)
46.73            ^^^^^^^^^^^^^^^^^^^^^^^^^
46.73   File "/usr/local/lib/python3.11/ssl.py", line 1167, in read
46.73     return self._sslobj.read(len, buffer)
46.73            ^^^^^^^^^^^^^^^^^^^^^^^^^^^^^^
46.73 TimeoutError: The read operation timed out
46.73
46.73 During handling of the above exception, another exception occurred:
46.73
46.73 Traceback (most recent call last):
46.73   File "/usr/local/lib/python3.11/site-packages/pip/_internal/cli/base_command.py", line 180, in exc_logging_wrapper
46.73     status = run_func(*args)
46.73              ^^^^^^^^^^^^^^^
46.73   File "/usr/local/lib/python3.11/site-packages/pip/_internal/cli/req_command.py", line 248, in wrapper
46.73     return func(self, options, args)
46.73            ^^^^^^^^^^^^^^^^^^^^^^^^^
46.73   File "/usr/local/lib/python3.11/site-packages/pip/_internal/commands/install.py", line 377, in run
46.73     requirement_set = resolver.resolve(
46.73                       ^^^^^^^^^^^^^^^^^
46.73   File "/usr/local/lib/python3.11/site-packages/pip/_internal/resolution/resolvelib/resolver.py", line 161, in resolve
46.73     self.factory.preparer.prepare_linked_requirements_more(reqs)
46.73   File "/usr/local/lib/python3.11/site-packages/pip/_internal/operations/prepare.py", line 565, in prepare_linked_requirements_more
46.73     self._complete_partial_requirements(
46.73   File "/usr/local/lib/python3.11/site-packages/pip/_internal/operations/prepare.py", line 479, in _complete_partial_requirements
46.73     for link, (filepath, _) in batch_download:
46.73   File "/usr/local/lib/python3.11/site-packages/pip/_internal/network/download.py", line 183, in __call__
46.73     for chunk in chunks:
46.73   File "/usr/local/lib/python3.11/site-packages/pip/_internal/cli/progress_bars.py", line 53, in _rich_progress_bar
46.73     for chunk in iterable:
46.73   File "/usr/local/lib/python3.11/site-packages/pip/_internal/network/utils.py", line 63, in response_chunks
46.73     for chunk in response.raw.stream(
46.73   File "/usr/local/lib/python3.11/site-packages/pip/_vendor/urllib3/response.py", line 622, in stream
46.73     data = self.read(amt=amt, decode_content=decode_content)
46.73            ^^^^^^^^^^^^^^^^^^^^^^^^^^^^^^^^^^^^^^^^^^^^^^^^^
46.73   File "/usr/local/lib/python3.11/site-packages/pip/_vendor/urllib3/response.py", line 560, in read
46.73     with self._error_catcher():
46.73   File "/usr/local/lib/python3.11/contextlib.py", line 158, in __exit__
46.73     self.gen.throw(typ, value, traceback)
46.73   File "/usr/local/lib/python3.11/site-packages/pip/_vendor/urllib3/response.py", line 443, in _error_catcher
46.73     raise ReadTimeoutError(self._pool, None, "Read timed out.")
46.73 pip._vendor.urllib3.exceptions.ReadTimeoutError: HTTPSConnectionPool(host='files.pythonhosted.org', port=443): Read timed out.
